<mujoco model="arm3d">
	<compiler coordinate="local" inertiafromgeom="true" angle="radian"/>
	<option timestep="0.01" iterations="20" gravity="0 0 0" integrator="Euler"/>
	<default >
		<joint armature="0.04" limited="true" damping="1"/>
		<geom condim="1" friction="0.8 0.1 0.1" density="300" margin="0.002" conaffinity="0" contype="0"/>
	</default>
	<worldbody >
		<light castshadow="false" dir="0 0 -1" pos="0 0 3" diffuse=".5 .5 .5"/>
		<geom type="plane" size="1 1 0.1" material="table" pos="0 0.5 -0.325" name="table" conaffinity="1" contype="1"/>
		<body pos="0 -0.6 0" name="r_shoulder_pan_link">
			<geom type="sphere" size="0.05" rgba="0.6 0.6 0.6 1" pos="-0.06 0.05 0.2" name="e1"/>
			<geom type="sphere" size="0.05" rgba="0.6 0.6 0.6 1" pos=" 0.06 0.05 0.2" name="e2"/>
			<geom type="sphere" size="0.03" rgba="0.1 0.1 0.1 1" pos="-0.06 0.09 0.2" name="e1p"/>
			<geom type="sphere" size="0.03" rgba="0.1 0.1 0.1 1" pos=" 0.06 0.09 0.2" name="e2p"/>
			<geom type="capsule" size="0.1" fromto="0 0 -0.4 0 0 0.2" name="sp"/>
			<joint type="hinge" damping="1.0" name="r_shoulder_pan_joint" axis="0 0 1" pos="0 0 0" range="-2.2854 1.714602"/>
			<body pos="0.1 0 0" name="r_shoulder_lift_link">
				<geom type="capsule" size="0.1" fromto="0 -0.1 0 0 0.1 0" name="sl"/>
				<joint type="hinge" damping="1.0" name="r_shoulder_lift_joint" axis="0 1 0" pos="0 0 0" range="-0.5236 1.3963"/>
				<body pos="0 0 0" name="r_upper_arm_roll_link">
					<geom type="capsule" size="0.02" fromto="-0.1 0 0 0.1 0 0" name="uar"/>
					<joint type="hinge" damping="0.1" name="r_upper_arm_roll_joint" axis="1 0 0" pos="0 0 0" range="-1.5 1.7"/>
					<body pos="0 0 0" name="r_upper_arm_link">
						<geom type="capsule" size="0.06" fromto="0 0 0 0.4 0 0" name="ua"/>
						<body pos="0.4 0 0" name="r_elbow_flex_link">
							<geom type="capsule" size="0.06" fromto="0 -0.02 0 0.0 0.02 0" name="ef"/>
							<joint type="hinge" damping="0.1" name="r_elbow_flex_joint" axis="0 1 0" pos="0 0 0" range="-2.3213 0"/>
							<body pos="0 0 0" name="r_forearm_roll_link">
								<geom type="capsule" size="0.02" fromto="-0.1 0 0 0.1 0 0" name="fr"/>
								<joint type="hinge" damping=".1" name="r_forearm_roll_joint" axis="1 0 0" pos="0 0 0" limited="true" range="-1.5 1.5"/>
								<body pos="0 0 0" name="r_forearm_link">
									<geom type="capsule" size="0.05" fromto="0 0 0 0.291 0 0" name="fa"/>
									<body pos="0.321 0 0" name="r_wrist_flex_link">
										<geom type="capsule" size="0.01" fromto="0 -0.02 0 0 0.02 0" name="wf"/>
										<joint type="hinge" damping=".1" name="r_wrist_flex_joint" axis="0 1 0" pos="0 0 0" range="-1.094 0"/>
										<body pos="0 0 0" name="r_wrist_roll_link">
											<joint type="hinge" damping="0.1" name="r_wrist_roll_joint" axis="1 0 0" pos="0 0 0" limited="true" range="-1.5 1.5"/>
											<body pos="0 0 0" name="tips_arm">
												<geom type="sphere" size="0.01" pos="0.1 -0.1 0." name="tip_arml"/>
												<geom type="sphere" size="0.01" pos="0.1 0.1 0." name="tip_armr"/>
											</body>
											<geom type="capsule" contype="1" size="0.02" fromto="0 -0.1 0. 0.0 +0.1 0" conaffinity="1"/>
											<geom type="capsule" contype="1" size="0.02" fromto="0 -0.1 0. 0.1 -0.1 0" conaffinity="1"/>
											<geom type="capsule" contype="1" size="0.02" fromto="0 +0.1 0. 0.1 +0.1 0" conaffinity="1"/>
										</body>
									</body>
								</body>
							</body>
						</body>
					</body>
				</body>
			</body>
		</body>
		<body pos="0.191510837983 -0.308489142296 -0.324" name="distractor">
			<light castshadow="false"/>
			<geom type="mesh" density="316.238132789" rgba="1 1 1 1" material="distractor" mesh="distractor_mesh" conaffinity="0" contype="1"/>
			<joint type="slide" damping="0.7839611182027526" name="distractor_slidey" axis="0 1 0" pos="0 0 0" range="-10.3213 10.3"/>
			<joint type="slide" damping="0.7839611182027526" name="distractor_slidex" axis="1 0 0" pos="0 0 0" range="-10.3213 10.3"/>
		</body>
		<body pos="0.45 -0.120835914908 -0.253164085092" name="object">
			<light castshadow="false"/>
			<geom type="mesh" density="2724.12496076" rgba="1 1 1 1" material="object" mesh="object_mesh" conaffinity="0" contype="1"/>
			<joint type="slide" damping="1.6518688927999807" name="obj_slidey" axis="0 1 0" pos="0 0 0" range="-10.3213 10.3"/>
			<joint type="slide" damping="1.6518688927999807" name="obj_slidex" axis="1 0 0" pos="0 0 0" range="-10.3213 10.3"/>
		</body>
		<body pos="0.45 -0.05 -0.323" name="goal">
			<geom type="cylinder" size="0.08 0.001 0.1" rgba="1 0 0 1" conaffinity="0" density="0.00001" contype="0"/>
			<joint type="slide" damping="0.5" name="goal_slidey" axis="0 1 0" pos="0 0 0" range="-10.3213 10.3"/>
			<joint type="slide" damping="0.5" name="goal_slidex" axis="1 0 0" pos="0 0 0" range="-10.3213 10.3"/>
		</body>
	</worldbody>
	<asset >
		<texture type="2d" file="textures/table_textures/wpic_002.png" name="table"/>
		<material specular="1" texture="table" rgba="0.9 0.9 0.9 1" shininess="0.3" name="table"/>
		<mesh scale="0.00177089787269 0.00177089787269 0.00177089787269" file="mujoco_models/tesaract.stl" name="object_mesh"/>
		<mesh scale="0.00258489162017 0.00258489162017 0.00258489162017" file="mujoco_models/nidoran_01.stl" name="distractor_mesh"/>
		<texture file="textures/obj_textures/waffled_0162.png" name="distractor"/>
		<material specular="1" texture="distractor" rgba="0.9 0.9 0.9 1" shininess="0.3" name="distractor"/>
		<texture file="textures/obj_textures/blotchy_0121.png" name="object"/>
		<material specular="1" texture="object" rgba="0.9 0.9 0.9 1" shininess="0.3" name="object"/>
	</asset>
	<actuator >
		<motor ctrllimited="true" joint="r_shoulder_pan_joint" ctrlrange="-2.0 2.0"/>
		<motor ctrllimited="true" joint="r_shoulder_lift_joint" ctrlrange="-2.0 2.0"/>
		<motor ctrllimited="true" joint="r_upper_arm_roll_joint" ctrlrange="-2.0 2.0"/>
		<motor ctrllimited="true" joint="r_elbow_flex_joint" ctrlrange="-2.0 2.0"/>
		<motor ctrllimited="true" joint="r_forearm_roll_joint" ctrlrange="-2.0 2.0"/>
		<motor ctrllimited="true" joint="r_wrist_flex_joint" ctrlrange="-2.0 2.0"/>
		<motor ctrllimited="true" joint="r_wrist_roll_joint" ctrlrange="-2.0 2.0"/>
	</actuator>
</mujoco>
