<mujoco model="reacher">
	<compiler inertiafromgeom="true" angle="radian"/>
	<default >
		<joint armature="1" damping="1" limited="true"/>
		<geom contype="0" friction="1 0.1 0.1" rgba="0.7 0.7 0 1"/>
	</default>
	<option integrator="RK4" gravity="0 0 -9.81" timestep="0.01"/>
	<worldbody >
		<geom conaffinity="0" name="root" contype="0" fromto="0 0 0 0 0 0.02" rgba="0.9 0.4 0.6 1" type="cylinder" size=".011"/>
		<body name="body0" pos="0 0 .01">
			<geom name="link0" type="capsule" fromto="0 0 0 0.1 0 0" rgba="0.0 0.4 0.6 1.0" size=".01"/>
			<joint limited="true" name="joint0" pos="0 0 0" range="-3.14 3.14" type="hinge" axis="0 0 1"/>
			<body name="body1" pos="0.1 0 0">
				<joint limited="true" name="joint1" pos="0 0 0" range="-3.0 3.0" type="hinge" axis="0 0 1"/>
				<geom name="link1" type="capsule" fromto="0 0 0 0.1 0 0" rgba="0.0 0.4 0.6 1.0" size=".01"/>
				<body name="fingertip" pos="0.11 0 0">
					<geom name="fingertip" pos="0 0 0" contype="0" rgba="0 1 0 1" type="sphere" size=".01"/>
				</body>
			</body>
		</body>
		<body name="target" pos="-0.0920436683314 -0.0329120467135 0.01">
			<geom conaffinity="0" density="0.00001" contype="0" rgba="0.6 0.5 0.8 1.0" type="box" size="0.03 0.03 0.03"/>
		</body>
		<body name="cube_0" pos="0.0687881833965 0.0497433216329 0.01">
			<geom conaffinity="0" density="0.00001" contype="0" rgba="0.1 0.4 0.5 1.0" type="box" size="0.03 0.03 0.03"/>
		</body>
		<body name="cube_1" pos="0.17625479334 -0.16987340162 0.01">
			<geom conaffinity="0" density="0.00001" contype="0" rgba="0.6 0.7 0.9 1.0" type="box" size="0.03 0.03 0.03"/>
		</body>
	</worldbody>
	<actuator >
		<motor ctrllimited="true" joint="joint0" ctrlrange="-1.0 1.0" gear="200.0"/>
		<motor ctrllimited="true" joint="joint1" ctrlrange="-1.0 1.0" gear="200.0"/>
	</actuator>
</mujoco>
